# 1. try catch

try 和 catch 是 C++ 的异常处理机制的一部分，用于处理运行时错误。通过 try 和 catch 块，你可以捕获和处理程序中的异常，从而防止程序崩溃并提供有意义的错误处理

基本语法
```cpp
try {
    // 可能会抛出异常的代码
} catch (const std::exception& e) {
    // 处理异常的代码
}
```

1. try 块
try 块包含可能会抛出异常的代码。当代码中发生异常时，程序控制权会转移到相应的 catch 块。

```cpp
try {
    // 可能会抛出异常的代码
    int result = 10 / 0; // 这行代码会抛出除零异常
}
```
2. catch 块
catch 块用于捕获异常并处理它。catch 块的参数可以是一个特定的异常类型，或者一个通用的基类类型，例如 std::exception。异常对象可以用于获取错误信息。

```cpp
catch (const std::exception& e) {
    // 处理异常的代码
    std::cerr << "Exception caught: " << e.what() << std::endl;
}
```

3. 多个 catch 块
你可以有多个 catch 块来处理不同类型的异常：
```cpp
try {
    // 可能会抛出多种异常的代码
} catch (const std::runtime_error& e) {
    // 处理运行时错误
    std::cerr << "Runtime error: " << e.what() << std::endl;
} catch (const std::out_of_range& e) {
    // 处理越界错误
    std::cerr << "Out of range error: " << e.what() << std::endl;
} catch (...) {
    // 捕获所有其他异常
    std::cerr << "Unknown exception occurred." << std::endl;
}
```

4. throw 语句
throw 语句用于抛出异常。异常对象通常是一个类的实例，能够提供错误信息或上下文。
```cpp
void function() {
    throw std::runtime_error("Something went wrong");
}
```

例子：
```cpp
#include <iostream>
#include <stdexcept>

int divide(int numerator, int denominator) {
    if (denominator == 0) {
        throw std::runtime_error("Division by zero");
    }
    return numerator / denominator;
}

int main() {
    try {
        int result = divide(10, 0); // 这将抛出异常
        std::cout << "Result: " << result << std::endl;
    } catch (const std::runtime_error& e) {
        std::cerr << "Caught an exception: " << e.what() << std::endl;
    }

    return 0;
}
```

## e.what()
e.what() 是 C++ 标准库中的异常类 std::exception 的成员函数，用于获取异常的描述信息。

e.what() 的作用
  描述异常：e.what() 返回一个 C 风格的字符串（const char*），通常是一个描述异常的简短消息。这对于调试和日志记录异常信息非常有用。

  标准异常类：std::exception 是所有标准异常类的基类。所有继承自 std::exception 的类（如 std::runtime_error、std::out_of_range 等）都实现了 what() 方法来提供错误信息。


自定义异常类
```cpp
#include <iostream>
#include <exception>

class MyException : public std::exception {
public:
    const char* what() const noexcept override {
        return "MyException occurred";
    }
};

int main() {
    try {
        throw MyException();
    } catch (const std::exception& e) {
        std::cerr << "Exception caught: " << e.what() << std::endl;
    }

    return 0;
}

```



